Workbook

Sheet Sheet1
A1: Day Ahead Hourly Ontario Zonal Energy Price Report
A2: 14th June
A3: Ontario Zonal Price & Components | B3: Day Ahead Zonal Energy Price ($/MWh) for hour
B4: 1 | C4: 2 | D4: 3 | E4: 4 | F4: 5 | G4: 6 | H4: 7 | I4: 8 | J4: 9 | K4: 10 | L4: 11 | M4: 12 | N4: 13 | O4: 14 | P4: 15 | Q4: 16 | R4: 17 | S4: 18 | T4: 19 | U4: 20 | V4: 21 | W4: 22 | X4: 23 | Y4: 24
A5: Zonal Price | B5: 26.79 | C5: 22.05 | D5: 22.31 | E5: 15.09 | F5: 17.72 | G5: 14.98 | H5: 20.23 | I5: 26.32 | J5: 29.12 | K5: 26.13 | L5: 29.22 | M5: 31.35 | N5: 32.13 | O5: 30.87 | P5: 31.2 | Q5: 41.65 | R5: 50.05 | S5: 54.84 | T5: 60.58 | U5: 56.54 | V5: 51 | W5: 37.54 | X5: 30.45 | Y5: 30.51
A6: Energy Loss Price | B6: 0.1 | C6: 0.12 | D6: 0.19 | E6: 0.13 | F6: 0.16 | G6: 0.1 | H6: 0.12 | I6: 0.06 | J6: 0 | K6: 0 | L6: 0.01 | M6: 0.07 | N6: 0.06 | O6: 0.08 | P6: 0.05 | Q6: -0.04 | R6: -0.23 | S6: -0.21 | T6: -0.24 | U6: -0.11 | V6: -0.02 | W6: 0.11 | X6: 0.11 | Y6: 0.18
A7: Energy Congestion Price | B7: -0.01 | C7: -0.03 | D7: -0.03 | E7: -0.01 | F7: -0.01 | G7: -0.01 | H7: -0.01 | I7: -0.01 | J7: -0.02 | K7: -0.02 | L7: -0.02 | M7: -0.02 | N7: -0.02 | O7: -0.02 | P7: -0.02 | Q7: -0.02 | R7: -0.01 | S7: -0.01 | T7: -0.01 | U7: -0.01 | V7: -0.03 | W7: -0.03 | X7: 0.15 | Y7: 0.17
A8: 14th May
A9: l Price & Components | B9: Day Ahead Zonal Energy Price ($/MWh) for hour
B10: 1 | C10: 2 | D10: 3 | E10: 4 | F10: 5 | G10: 6 | H10: 7 | I10: 8 | J10: 9 | K10: 10 | L10: 11 | M10: 12 | N10: 13 | O10: 14 | P10: 15 | Q10: 16 | R10: 17 | S10: 18 | T10: 19 | U10: 20 | V10: 21 | W10: 22 | X10: 23 | Y10: 24
A11: Zonal Price | B11: 11.94 | C11: 6.78 | D11: 6.82 | E11: 6.94 | F11: 14.07 | G11: 30.4 | H11: 30.31 | I11: 35.63 | J11: 36.11 | K11: 37.09 | L11: 36.47 | M11: 36.34 | N11: 36.24 | O11: 36.29 | P11: 35.41 | Q11: 35.47 | R11: 56.07 | S11: 63.62 | T11: 60.62 | U11: 57.49 | V11: 41.4 | W11: 36.26 | X11: 28.64 | Y11: 11.95
A12: Energy Loss Price | B12: 0.04 | C12: 0.04 | D12: 0.05 | E12: 0.05 | F12: 0.09 | G12: 0.16 | H12: 0.09 | I12: 0.07 | J12: 0.03 | K12: 0.08 | L12: 0.02 | M12: 0.02 | N12: -0.06 | O12: -0.04 | P12: -0.02 | Q12: -0.04 | R12: -0.06 | S12: -0.07 | T12: -0.06 | U12: -0.07 | V12: -0.04 | W12: 0 | X12: -0.04 | Y12: 0.01
A13: Energy Congestion Price | B13: 0 | C13: 0 | D13: 0 | E13: 0 | F13: 0 | G13: -0.5 | H13: -0.48 | I13: -1.32 | J13: -1.5 | K13: -0.6 | L13: -0.57 | M13: -0.59 | N13: -0.59 | O13: -0.55 | P13: -1.42 | Q13: -1.46 | R13: -2.19 | S13: -2.74 | T13: -1.04 | U13: -1 | V13: -0.68 | W13: -0.53 | X13: -0.49 | Y13: -0.11
A14: 15th May
A15: Ontario Zonal Price & Components | B15: Day Ahead Zonal Energy Price ($/MWh) for hour
B16: 1 | C16: 2 | D16: 3 | E16: 4 | F16: 5 | G16: 6 | H16: 7 | I16: 8 | J16: 9 | K16: 10 | L16: 11 | M16: 12 | N16: 13 | O16: 14 | P16: 15 | Q16: 16 | R16: 17 | S16: 18 | T16: 19 | U16: 20 | V16: 21 | W16: 22 | X16: 23 | Y16: 24
A17: Zonal Price | B17: 5.93 | C17: 5.94 | D17: 5.91 | E17: 6.13 | F17: 5.83 | G17: 6.89 | H17: 12.95 | I17: 13.24 | J17: 28.52 | K17: 28.21 | L17: 25.94 | M17: 29.38 | N17: 28.2 | O17: 29.89 | P17: 29.81 | Q17: 36.23 | R17: 57.61 | S17: 59.92 | T17: 58.81 | U17: 69.17 | V17: 56.34 | W17: 36.24 | X17: 29.05 | Y17: 11.9
A18: Energy Loss Price | B18: 0.02 | C18: 0.03 | D18: 0.04 | E18: 0.04 | F18: 0.04 | G18: 0.02 | H18: -0.04 | I18: -0.05 | J18: -0.13 | K18: -0.04 | L18: -0.05 | M18: -0.04 | N18: -0.11 | O18: -0.11 | P18: -0.1 | Q18: -0.09 | R18: -0.08 | S18: -0.1 | T18: -0.12 | U18: -0.13 | V18: -0.1 | W18: -0.07 | X18: -0.06 | Y18: 0.01
A19: Energy Congestion Price | B19: 0 | C19: 0 | D19: 0 | E19: 0 | F19: 0 | G19: 0 | H19: -0.12 | I19: -0.12 | J19: -0.4 | K19: -0.43 | L19: -0.36 | M19: -0.45 | N19: -0.63 | O19: -1.04 | P19: -1.07 | Q19: -1.32 | R19: -2.37 | S19: -2.51 | T19: -1.18 | U19: -1.18 | V19: -0.93 | W19: -0.61 | X19: -0.48 | Y19: -0.11
A20: 16th May
A21: Ontario Zonal Price & Components | B21: Day Ahead Zonal Energy Price ($/MWh) for hour
B22: 1 | C22: 2 | D22: 3 | E22: 4 | F22: 5 | G22: 6 | H22: 7 | I22: 8 | J22: 9 | K22: 10 | L22: 11 | M22: 12 | N22: 13 | O22: 14 | P22: 15 | Q22: 16 | R22: 17 | S22: 18 | T22: 19 | U22: 20 | V22: 21 | W22: 22 | X22: 23 | Y22: 24
A23: Zonal Price | B23: 5.31 | C23: 0 | D23: 0 | E23: 0 | F23: 0 | G23: 0 | H23: 0 | I23: 6.13 | J23: 6.57 | K23: 9.94 | L23: 9.93 | M23: 7.6 | N23: 6.35 | O23: 6.14 | P23: 6.04 | Q23: 6.4 | R23: 7.73 | S23: 12.14 | T23: 13.83 | U23: 12.25 | V23: 10.86 | W23: 6.62 | X23: 5.29 | Y23: 0
A24: Energy Loss Price | B24: 0.05 | C24: 0 | D24: 0 | E24: 0 | F24: 0 | G24: 0 | H24: 0 | I24: 0.02 | J24: -0.01 | K24: -0.02 | L24: -0.04 | M24: -0.02 | N24: -0.01 | O24: -0.01 | P24: -0.01 | Q24: -0.01 | R24: -0.03 | S24: -0.06 | T24: -0.06 | U24: -0.04 | V24: -0.06 | W24: -0.01 | X24: 0.03 | Y24: 0
A25: Energy Congestion Price | B25: 0 | C25: 0 | D25: 0 | E25: 0 | F25: 0 | G25: 0 | H25: 0 | I25: 0 | J25: 0 | K25: -0.06 | L25: -0.06 | M25: 0 | N25: 0 | O25: 0 | P25: 0 | Q25: 0 | R25: 0 | S25: -0.1 | T25: -0.14 | U25: 0 | V25: -0.07 | W25: 0 | X25: 0 | Y25: 0
A26: 17th May
A27: Ontario Zonal Price & Components | B27: Day Ahead Zonal Energy Price ($/MWh) for hour
B28: 1 | C28: 2 | D28: 3 | E28: 4 | F28: 5 | G28: 6 | H28: 7 | I28: 8 | J28: 9 | K28: 10 | L28: 11 | M28: 12 | N28: 13 | O28: 14 | P28: 15 | Q28: 16 | R28: 17 | S28: 18 | T28: 19 | U28: 20 | V28: 21 | W28: 22 | X28: 23 | Y28: 24
A29: Zonal Price | B29: 0 | C29: 0 | D29: 0 | E29: 0 | F29: 0 | G29: 0 | H29: 0 | I29: 5.77 | J29: 6.2 | K29: 9.96 | L29: 14.02 | M29: 14.17 | N29: 14.01 | O29: 15.35 | P29: 14.17 | Q29: 14.15 | R29: 32.89 | S29: 33.65 | T29: 35.86 | U29: 39.87 | V29: 35.34 | W29: 33.35 | X29: 24.78 | Y29: 14.58
A30: Energy Loss Price | B30: 0 | C30: 0 | D30: 0 | E30: 0 | F30: 0 | G30: 0 | H30: 0 | I30: 0.03 | J30: 0.01 | K30: 0.01 | L30: -0.01 | M30: 0 | N30: -0.03 | O30: -0.04 | P30: -0.01 | Q30: -0.04 | R30: -0.07 | S30: -0.05 | T30: -0.01 | U30: -0.01 | V30: -0.01 | W30: 0.04 | X30: 0.05 | Y30: 0.08
A31: Energy Congestion Price | B31: 0 | C31: 0 | D31: 0 | E31: 0 | F31: 0 | G31: 0 | H31: 0 | I31: 0 | J31: 0 | K31: -0.06 | L31: -0.16 | M31: -0.15 | N31: -0.15 | O31: -0.19 | P31: -0.15 | Q31: -0.15 | R31: -0.53 | S31: -0.55 | T31: 0 | U31: 0 | V31: 0 | W31: 0 | X31: -0.01 | Y31: 0
A32: 18th May
A33: Ontario Zonal Price & Components | B33: Day Ahead Zonal Energy Price ($/MWh) for hour
B34: 1 | C34: 2 | D34: 3 | E34: 4 | F34: 5 | G34: 6 | H34: 7 | I34: 8 | J34: 9 | K34: 10 | L34: 11 | M34: 12 | N34: 13 | O34: 14 | P34: 15 | Q34: 16 | R34: 17 | S34: 18 | T34: 19 | U34: 20 | V34: 21 | W34: 22 | X34: 23 | Y34: 24
A35: Zonal Price | B35: 6.02 | C35: 5.74 | D35: 5.59 | E35: 5.88 | F35: 6.32 | G35: 6.37 | H35: 6.21 | I35: 6.75 | J35: 6.67 | K35: 6.58 | L35: 6.25 | M35: 6.36 | N35: 5.83 | O35: 5.86 | P35: 5.96 | Q35: 6.74 | R35: 14.54 | S35: 29.88 | T35: 38.08 | U35: 57.69 | V35: 39.31 | W35: 14.54 | X35: 14.51 | Y35: 14.77
A36: Energy Loss Price | B36: 0.06 | C36: 0.08 | D36: 0.09 | E36: 0.09 | F36: 0.08 | G36: 0.06 | H36: 0.05 | I36: 0.04 | J36: 0.03 | K36: 0.04 | L36: 0.03 | M36: 0.04 | N36: 0.03 | O36: 0.03 | P36: 0.03 | Q36: 0.01 | R36: -0.01 | S36: -0.07 | T36: -0.11 | U36: -0.14 | V36: -0.15 | W36: -0.02 | X36: 0.04 | Y36: 0.11
A37: Energy Congestion Price | B37: 0 | C37: 0 | D37: 0 | E37: 0 | F37: 0 | G37: 0 | H37: 0 | I37: 0 | J37: 0 | K37: 0 | L37: 0 | M37: 0 | N37: 0 | O37: 0 | P37: 0 | Q37: 0 | R37: -0.13 | S37: -0.44 | T37: -0.62 | U37: -1.04 | V37: -0.71 | W37: -0.15 | X37: -0.18 | Y37: 0
A38: 19th May
A39: Ontario Zonal Price & Components | B39: Day Ahead Zonal Energy Price ($/MWh) for hour
B40: 1 | C40: 2 | D40: 3 | E40: 4 | F40: 5 | G40: 6 | H40: 7 | I40: 8 | J40: 9 | K40: 10 | L40: 11 | M40: 12 | N40: 13 | O40: 14 | P40: 15 | Q40: 16 | R40: 17 | S40: 18 | T40: 19 | U40: 20 | V40: 21 | W40: 22 | X40: 23 | Y40: 24
...

Sheet Sheet2
A1: Date | B1: Day Ahead Zonal Energy Price ($/MWh) for hour | C1: {=TRANSPOSE(Sheet1!A5:A7)} -> Zonal Price | D1: Energy Loss Price | E1: Energy Congestion Price
A2: 45791.522 | B2: {=TRANSPOSE(Sheet1!B10:Y13)} -> 1 | C2: 11.94 | D2: 0.04 | E2: 0
A3: 45791.522 | B3: 2 | C3: 6.78 | D3: 0.04 | E3: 0
A4: 45791.522 | B4: 3 | C4: 6.82 | D4: 0.05 | E4: 0
A5: 45791.522 | B5: 4 | C5: 6.94 | D5: 0.05 | E5: 0
A6: 45791.522 | B6: 5 | C6: 14.07 | D6: 0.09 | E6: 0
A7: 45791.522 | B7: 6 | C7: 30.4 | D7: 0.16 | E7: -0.5
A8: 45791.522 | B8: 7 | C8: 30.31 | D8: 0.09 | E8: -0.48
A9: 45791.522 | B9: 8 | C9: 35.63 | D9: 0.07 | E9: -1.32
A10: 45791.522 | B10: 9 | C10: 36.11 | D10: 0.03 | E10: -1.5
A11: 45791.522 | B11: 10 | C11: 37.09 | D11: 0.08 | E11: -0.6
A12: 45791.522 | B12: 11 | C12: 36.47 | D12: 0.02 | E12: -0.57
A13: 45791.522 | B13: 12 | C13: 36.34 | D13: 0.02 | E13: -0.59
A14: 45791.522 | B14: 13 | C14: 36.24 | D14: -0.06 | E14: -0.59
... A25: 45791.522 | B25: 24 | C25: 11.95 | D25: 0.01 | E25: -0.11
A26: 45792.522 | B26: {=TRANSPOSE(Sheet1!B16:Y19)} -> 1 | C26: 5.93 | D26: 0.02 | E26: 0
A27: 45792.522 | B27: 2 | C27: 5.94 | D27: 0.03 | E27: 0
A28: 45792.522 | B28: 3 | C28: 5.91 | D28: 0.04 | E28: 0
A29: 45792.522 | B29: 4 | C29: 6.13 | D29: 0.04 | E29: 0
A30: 45792.522 | B30: 5 | C30: 5.83 | D30: 0.04 | E30: 0
A31: 45792.522 | B31: 6 | C31: 6.89 | D31: 0.02 | E31: 0
A32: 45792.522 | B32: 7 | C32: 12.95 | D32: -0.04 | E32: -0.12
A33: 45792.522 | B33: 8 | C33: 13.24 | D33: -0.05 | E33: -0.12
A34: 45792.522 | B34: 9 | C34: 28.52 | D34: -0.13 | E34: -0.4
A35: 45792.522 | B35: 10 | C35: 28.21 | D35: -0.04 | E35: -0.43
A36: 45792.522 | B36: 11 | C36: 25.94 | D36: -0.05 | E36: -0.36
A37: 45792.522 | B37: 12 | C37: 29.38 | D37: -0.04 | E37: -0.45
A38: 45792.522 | B38: 13 | C38: 28.2 | D38: -0.11 | E38: -0.63
... A49: 45792.522 | B49: 24 | C49: 11.9 | D49: 0.01 | E49: -0.11
A50: 45793.522 | B50: {=TRANSPOSE(Sheet1!B22:Y25)} -> 1 | C50: 5.31 | D50: 0.05 | E50: 0
A51: 45793.522 | B51: 2 | C51: 0 | D51: 0 | E51: 0
A52: 45793.522 | B52: 3 | C52: 0 | D52: 0 | E52: 0
A53: 45793.522 | B53: 4 | C53: 0 | D53: 0 | E53: 0
A54: 45793.522 | B54: 5 | C54: 0 | D54: 0 | E54: 0
A55: 45793.522 | B55: 6 | C55: 0 | D55: 0 | E55: 0
A56: 45793.522 | B56: 7 | C56: 0 | D56: 0 | E56: 0
A57: 45793.522 | B57: 8 | C57: 6.13 | D57: 0.02 | E57: 0
A58: 45793.522 | B58: 9 | C58: 6.57 | D58: -0.01 | E58: 0
A59: 45793.522 | B59: 10 | C59: 9.94 | D59: -0.02 | E59: -0.06
A60: 45793.522 | B60: 11 | C60: 9.93 | D60: -0.04 | E60: -0.06
...
